2020-01-26 10:35:56,251 [INFO ]  Starting Rasa server on http://localhost:5005
2020-01-26 10:36:17,218 [INFO ]  Entry Point [tensor2tensor.envs.tic_tac_toe_env:TicTacToeEnv] registered with id [T2TEnv-TicTacToeEnv-v0]
2020-01-26 10:36:21,855 [ERROR]  Experienced exception while trying to serve
Traceback (most recent call last):
  File "/Users/bhuvaneshwari/venv/lib/python3.7/site-packages/sanic/server.py", line 860, in serve
    http_server = loop.run_until_complete(server_coroutine)
  File "uvloop/loop.pyx", line 1456, in uvloop.loop.Loop.run_until_complete
  File "uvloop/loop.pyx", line 1727, in create_server
OSError: [Errno 48] error while attempting to bind on address ('0.0.0.0', 5005): address already in use

During handling of the above exception, another exception occurred:

Traceback (most recent call last):
  File "/Library/Developer/CommandLineTools/Library/Frameworks/Python3.framework/Versions/3.7/lib/python3.7/logging/__init__.py", line 1034, in emit
    msg = self.format(record)
  File "/Library/Developer/CommandLineTools/Library/Frameworks/Python3.framework/Versions/3.7/lib/python3.7/logging/__init__.py", line 880, in format
    return fmt.format(record)
  File "/Library/Developer/CommandLineTools/Library/Frameworks/Python3.framework/Versions/3.7/lib/python3.7/logging/__init__.py", line 627, in format
    record.exc_text = self.formatException(record.exc_info)
  File "/Library/Developer/CommandLineTools/Library/Frameworks/Python3.framework/Versions/3.7/lib/python3.7/logging/__init__.py", line 577, in formatException
    traceback.print_exception(ei[0], ei[1], tb, None, sio)
  File "/Library/Developer/CommandLineTools/Library/Frameworks/Python3.framework/Versions/3.7/lib/python3.7/traceback.py", line 104, in print_exception
    type(value), value, tb, limit=limit).format(chain=chain):
  File "/Library/Developer/CommandLineTools/Library/Frameworks/Python3.framework/Versions/3.7/lib/python3.7/traceback.py", line 508, in __init__
    capture_locals=capture_locals)
  File "/Library/Developer/CommandLineTools/Library/Frameworks/Python3.framework/Versions/3.7/lib/python3.7/traceback.py", line 363, in extract
    f.line
  File "/Library/Developer/CommandLineTools/Library/Frameworks/Python3.framework/Versions/3.7/lib/python3.7/traceback.py", line 285, in line
    self._line = linecache.getline(self.filename, self.lineno).strip()
  File "/Library/Developer/CommandLineTools/Library/Frameworks/Python3.framework/Versions/3.7/lib/python3.7/linecache.py", line 16, in getline
    lines = getlines(filename, module_globals)
  File "/Library/Developer/CommandLineTools/Library/Frameworks/Python3.framework/Versions/3.7/lib/python3.7/linecache.py", line 48, in getlines
    for mod in sys.modules.values():
RuntimeError: dictionary changed size during iteration

During handling of the above exception, another exception occurred:

Traceback (most recent call last):
  File "/Users/bhuvaneshwari/venv/lib/python3.7/site-packages/sanic/app.py", line 1133, in run
    serve(**server_settings)
  File "/Users/bhuvaneshwari/venv/lib/python3.7/site-packages/sanic/server.py", line 862, in serve
    logger.exception("Unable to start server")
  File "/Library/Developer/CommandLineTools/Library/Frameworks/Python3.framework/Versions/3.7/lib/python3.7/logging/__init__.py", line 1418, in exception
    self.error(msg, *args, exc_info=exc_info, **kwargs)
  File "/Library/Developer/CommandLineTools/Library/Frameworks/Python3.framework/Versions/3.7/lib/python3.7/logging/__init__.py", line 1412, in error
    self._log(ERROR, msg, args, **kwargs)
  File "/Library/Developer/CommandLineTools/Library/Frameworks/Python3.framework/Versions/3.7/lib/python3.7/logging/__init__.py", line 1519, in _log
    self.handle(record)
  File "/Library/Developer/CommandLineTools/Library/Frameworks/Python3.framework/Versions/3.7/lib/python3.7/logging/__init__.py", line 1529, in handle
    self.callHandlers(record)
  File "/Library/Developer/CommandLineTools/Library/Frameworks/Python3.framework/Versions/3.7/lib/python3.7/logging/__init__.py", line 1591, in callHandlers
    hdlr.handle(record)
  File "/Library/Developer/CommandLineTools/Library/Frameworks/Python3.framework/Versions/3.7/lib/python3.7/logging/__init__.py", line 905, in handle
    self.emit(record)
  File "/Library/Developer/CommandLineTools/Library/Frameworks/Python3.framework/Versions/3.7/lib/python3.7/logging/__init__.py", line 1040, in emit
    self.handleError(record)
  File "/Library/Developer/CommandLineTools/Library/Frameworks/Python3.framework/Versions/3.7/lib/python3.7/logging/__init__.py", line 958, in handleError
    traceback.print_exception(t, v, tb, None, sys.stderr)
  File "/Library/Developer/CommandLineTools/Library/Frameworks/Python3.framework/Versions/3.7/lib/python3.7/traceback.py", line 104, in print_exception
    type(value), value, tb, limit=limit).format(chain=chain):
  File "/Library/Developer/CommandLineTools/Library/Frameworks/Python3.framework/Versions/3.7/lib/python3.7/traceback.py", line 521, in __init__
    self._load_lines()
  File "/Library/Developer/CommandLineTools/Library/Frameworks/Python3.framework/Versions/3.7/lib/python3.7/traceback.py", line 533, in _load_lines
    self.__context__._load_lines()
  File "/Library/Developer/CommandLineTools/Library/Frameworks/Python3.framework/Versions/3.7/lib/python3.7/traceback.py", line 531, in _load_lines
    frame.line
  File "/Library/Developer/CommandLineTools/Library/Frameworks/Python3.framework/Versions/3.7/lib/python3.7/traceback.py", line 285, in line
    self._line = linecache.getline(self.filename, self.lineno).strip()
  File "/Library/Developer/CommandLineTools/Library/Frameworks/Python3.framework/Versions/3.7/lib/python3.7/linecache.py", line 16, in getline
    lines = getlines(filename, module_globals)
  File "/Library/Developer/CommandLineTools/Library/Frameworks/Python3.framework/Versions/3.7/lib/python3.7/linecache.py", line 48, in getlines
    for mod in sys.modules.values():
RuntimeError: dictionary changed size during iteration
